<robot name="SimpleArmModelforURDF">
  <material name="silver">
    <color rgba="0.700 0.700 0.700 1.000"/>
  </material>
  <transmission name="Rev2_tran">
    <type>transmission_interface/SimpleTransmission</type>
    <joint name="Rev2">
      <hardwareInterface>hardware_interface/EffortJointInterface</hardwareInterface>
    </joint>
    <actuator name="Rev2_actr">
      <hardwareInterface>hardware_interface/EffortJointInterface</hardwareInterface>
      <mechanicalReduction>1</mechanicalReduction>
    </actuator>
  </transmission>
  <transmission name="Rev3_tran">
    <type>transmission_interface/SimpleTransmission</type>
    <joint name="Rev3">
      <hardwareInterface>hardware_interface/EffortJointInterface</hardwareInterface>
    </joint>
    <actuator name="Rev3_actr">
      <hardwareInterface>hardware_interface/EffortJointInterface</hardwareInterface>
      <mechanicalReduction>1</mechanicalReduction>
    </actuator>
  </transmission>
  <transmission name="Rev4_tran">
    <type>transmission_interface/SimpleTransmission</type>
    <joint name="Rev4">
      <hardwareInterface>hardware_interface/EffortJointInterface</hardwareInterface>
    </joint>
    <actuator name="Rev4_actr">
      <hardwareInterface>hardware_interface/EffortJointInterface</hardwareInterface>
      <mechanicalReduction>1</mechanicalReduction>
    </actuator>
  </transmission>
  <transmission name="Rev5_tran">
    <type>transmission_interface/SimpleTransmission</type>
    <joint name="Rev5">
      <hardwareInterface>hardware_interface/EffortJointInterface</hardwareInterface>
    </joint>
    <actuator name="Rev5_actr">
      <hardwareInterface>hardware_interface/EffortJointInterface</hardwareInterface>
      <mechanicalReduction>1</mechanicalReduction>
    </actuator>
  </transmission>
  <transmission name="Rev6_tran">
    <type>transmission_interface/SimpleTransmission</type>
    <joint name="Rev6">
      <hardwareInterface>hardware_interface/EffortJointInterface</hardwareInterface>
    </joint>
    <actuator name="Rev6_actr">
      <hardwareInterface>hardware_interface/EffortJointInterface</hardwareInterface>
      <mechanicalReduction>1</mechanicalReduction>
    </actuator>
  </transmission>
  <gazebo>
    <plugin filename="libgazebo_ros_control.so" name="control"/>
  </gazebo>
  <gazebo reference="base_link">
    <material>Gazebo/Silver</material>
    <mu1>0.2</mu1>
    <mu2>0.2</mu2>
    <selfCollide>true</selfCollide>
    <gravity>true</gravity>
  </gazebo>
  <gazebo reference="link2_1">
    <material>Gazebo/Silver</material>
    <mu1>0.2</mu1>
    <mu2>0.2</mu2>
    <selfCollide>true</selfCollide>
  </gazebo>
  <gazebo reference="link3_1">
    <material>Gazebo/Silver</material>
    <mu1>0.2</mu1>
    <mu2>0.2</mu2>
    <selfCollide>true</selfCollide>
  </gazebo>
  <gazebo reference="link4_1">
    <material>Gazebo/Silver</material>
    <mu1>0.2</mu1>
    <mu2>0.2</mu2>
    <selfCollide>true</selfCollide>
  </gazebo>
  <gazebo reference="link5_1">
    <material>Gazebo/Silver</material>
    <mu1>0.2</mu1>
    <mu2>0.2</mu2>
    <selfCollide>true</selfCollide>
  </gazebo>
  <gazebo reference="hand_1">
    <material>Gazebo/Silver</material>
    <mu1>0.2</mu1>
    <mu2>0.2</mu2>
    <selfCollide>true</selfCollide>
  </gazebo>
  <link name="base_link">
    <inertial>
      <origin rpy="0 0 0" xyz="0.07232649188416126 -0.09791477407890314 -0.0008886360294599971"/>
      <mass value="20.44018084917099"/>
      <inertia ixx="0.117459" ixy="-0.0" ixz="0.0" iyy="0.059326" iyz="0.002483" izz="0.14262"/>
    </inertial>
    <visual>
      <origin rpy="0 0 0" xyz="0 0 0"/>
      <geometry>
        <mesh filename="package://SimpleArmModelforURDF_description/meshes/base_link.stl" scale="0.001 0.001 0.001"/>
      </geometry>
      <material name="silver"/>
    </visual>
    <collision>
      <origin rpy="0 0 0" xyz="0 0 0"/>
      <geometry>
        <mesh filename="package://SimpleArmModelforURDF_description/meshes/base_link.stl" scale="0.001 0.001 0.001"/>
      </geometry>
    </collision>
  </link>
  <link name="link2_1">
    <inertial>
      <origin rpy="0 0 0" xyz="0.0269480213431868 0.05289027565620781 0.05870989072982183"/>
      <mass value="0.7163419742129765"/>
      <inertia ixx="0.001378" ixy="-0.000216" ixz="-0.000475" iyy="0.00236" iyz="-0.000335" izz="0.002097"/>
    </inertial>
    <visual>
      <origin rpy="0 0 0" xyz="-0.072326 0.050475 -0.065748"/>
      <geometry>
        <mesh filename="package://SimpleArmModelforURDF_description/meshes/link2_1.stl" scale="0.001 0.001 0.001"/>
      </geometry>
      <material name="silver"/>
    </visual>
    <collision>
      <origin rpy="0 0 0" xyz="-0.072326 0.050475 -0.065748"/>
      <geometry>
        <mesh filename="package://SimpleArmModelforURDF_description/meshes/link2_1.stl" scale="0.001 0.001 0.001"/>
      </geometry>
    </collision>
  </link>
  <link name="link3_1">
    <inertial>
      <origin rpy="0 0 0" xyz="0.005197044122406919 0.12734378296717147 0.00024921156093693497"/>
      <mass value="0.575294345342291"/>
      <inertia ixx="0.005763" ixy="0.000657" ixz="-6e-06" iyy="0.000753" iyz="2e-05" izz="0.006144"/>
    </inertial>
    <visual>
      <origin rpy="0 0 0" xyz="-0.027876 -0.013726 -0.148317"/>
      <geometry>
        <mesh filename="package://SimpleArmModelforURDF_description/meshes/link3_1.stl" scale="0.001 0.001 0.001"/>
      </geometry>
      <material name="silver"/>
    </visual>
    <collision>
      <origin rpy="0 0 0" xyz="-0.027876 -0.013726 -0.148317"/>
      <geometry>
        <mesh filename="package://SimpleArmModelforURDF_description/meshes/link3_1.stl" scale="0.001 0.001 0.001"/>
      </geometry>
    </collision>
  </link>
  <link name="link4_1">
    <inertial>
      <origin rpy="0 0 0" xyz="0.032265119521303245 0.007943767613698915 0.04382126030642447"/>
      <mass value="0.5683984289895797"/>
      <inertia ixx="0.004471" ixy="-9e-06" ixz="2.4e-05" iyy="0.004385" iyz="0.000241" izz="0.000493"/>
    </inertial>
    <visual>
      <origin rpy="0 0 0" xyz="-0.042876 -0.318726 -0.148317"/>
      <geometry>
        <mesh filename="package://SimpleArmModelforURDF_description/meshes/link4_1.stl" scale="0.001 0.001 0.001"/>
      </geometry>
      <material name="silver"/>
    </visual>
    <collision>
      <origin rpy="0 0 0" xyz="-0.042876 -0.318726 -0.148317"/>
      <geometry>
        <mesh filename="package://SimpleArmModelforURDF_description/meshes/link4_1.stl" scale="0.001 0.001 0.001"/>
      </geometry>
    </collision>
  </link>
  <link name="link5_1">
    <inertial>
      <origin rpy="0 0 0" xyz="0.03133868648272104 1.3960485362285446e-05 -0.01226113551012753"/>
      <mass value="0.10457251015807814"/>
      <inertia ixx="5e-05" ixy="-0.0" ixz="6e-06" iyy="6.8e-05" iyz="-0.0" izz="4.1e-05"/>
    </inertial>
    <visual>
      <origin rpy="0 0 0" xyz="-0.045076 -0.318726 -0.371158"/>
      <geometry>
        <mesh filename="package://SimpleArmModelforURDF_description/meshes/link5_1.stl" scale="0.001 0.001 0.001"/>
      </geometry>
      <material name="silver"/>
    </visual>
    <collision>
      <origin rpy="0 0 0" xyz="-0.045076 -0.318726 -0.371158"/>
      <geometry>
        <mesh filename="package://SimpleArmModelforURDF_description/meshes/link5_1.stl" scale="0.001 0.001 0.001"/>
      </geometry>
    </collision>
  </link>
  <link name="hand_1">
    <inertial>
      <origin rpy="0 0 0" xyz="-0.080858 -0.318726 -0.392348"/>
      <mass value="0.0"/>
      <inertia ixx="0.0" ixy="0.0" ixz="0.0" iyy="0.0" iyz="0.0" izz="0.0"/>
    </inertial>
    <visual>
      <origin rpy="0 0 0" xyz="-0.080858 -0.318726 -0.392348"/>
      <geometry>
        <mesh filename="package://SimpleArmModelforURDF_description/meshes/hand_1.stl" scale="0.001 0.001 0.001"/>
      </geometry>
      <material name="silver"/>
    </visual>
    <collision>
      <origin rpy="0 0 0" xyz="-0.080858 -0.318726 -0.392348"/>
      <geometry>
        <mesh filename="package://SimpleArmModelforURDF_description/meshes/hand_1.stl" scale="0.001 0.001 0.001"/>
      </geometry>
    </collision>
  </link>
  <joint name="Rev2" type="revolute">
    <origin rpy="0 0 0" xyz="0.072326 -0.050475 0.065748"/>
    <parent link="base_link"/>
    <child link="link2_1"/>
    <limit lower="0" upper="180" /> 
    <axis xyz="-0.0 0.0 1.0"/>
  </joint>
  <joint name="Rev3" type="revolute">
    <origin rpy="0 0 0" xyz="-0.04445 0.064201 0.082569"/>
    <parent link="link2_1"/>
    <child link="link3_1"/>
    <limit lower="0" upper="3.14" /> 
    <axis xyz="-1.0 -0.0 -0.0"/>
  </joint>
  <joint name="Rev4" type="revolute">
    <origin rpy="0 0 0" xyz="0.015 0.305 0.0"/>
    <parent link="link3_1"/>
    <child link="link4_1"/>
    <limit lower="0" upper="6.28" /> 
    <axis xyz="-1.0 -0.0 -0.0"/>
  </joint>
  <joint name="Rev5" type="revolute">
    <origin rpy="0 0 0" xyz="0.0022 0.0 0.222841"/>
    <parent link="link4_1"/>
    <child link="link5_1"/>
    <limit lower="0" upper="3" /> 
    <axis xyz="1.0 0.0 -0.0"/>
  </joint>
  <joint name="Rev6" type="revolute">
    <origin rpy="0 0 0" xyz="0.035782 0.0 0.02119"/>
    <parent link="link5_1"/>
    <child link="hand_1"/>
    <limit lower="0" upper="6.28" /> 
    <axis xyz="-0.0 0.0 1.0"/>
  </joint>
</robot>

